Workbook

Sheet Cat.1
A1: Classement Cat.1 | B1: N° de Dossard | C1: Nom Prénom | D1: Club
A2: 1 | B2: 2 | C2: =_xlfn.XLOOKUP(B2,Liste_Dossards!A:A,Liste_Dossards!B:B,"") -> FRITSH NICOLAS | D2: =_xlfn.XLOOKUP(C2,Liste_Dossards!B:B,Liste_Dossards!C:C,"") -> UC VOIRONNAISE
A3: 2 | B3: 1 | C3: =_xlfn.XLOOKUP(B3,Liste_Dossards!A:A,Liste_Dossards!B:B,"") -> CONTI GUILLAUME | D3: =_xlfn.XLOOKUP(C3,Liste_Dossards!B:B,Liste_Dossards!C:C,"") -> TEAM JALLET AUTO
A4: 3 | B4: 3 | C4: =_xlfn.XLOOKUP(B4,Liste_Dossards!A:A,Liste_Dossards!B:B,"") -> GAUTHIER--PHILIPPE ERWIN | D4: =_xlfn.XLOOKUP(C4,Liste_Dossards!B:B,Liste_Dossards!C:C,"") -> LAC ALIANCE CYCLISTE
A5: 4 | B5: 10 | C5: =_xlfn.XLOOKUP(B5,Liste_Dossards!A:A,Liste_Dossards!B:B,"") -> VERNEY FREDERIC | D5: =_xlfn.XLOOKUP(C5,Liste_Dossards!B:B,Liste_Dossards!C:C,"") -> TEAM JALLET AUTO
A6: 5 | B6: 4 | C6: =_xlfn.XLOOKUP(B6,Liste_Dossards!A:A,Liste_Dossards!B:B,"") -> GIRAUD MATTHIEU | D6: =_xlfn.XLOOKUP(C6,Liste_Dossards!B:B,Liste_Dossards!C:C,"") -> UC RIVES
A7: 6 | B7: 11 | C7: =_xlfn.XLOOKUP(B7,Liste_Dossards!A:A,Liste_Dossards!B:B,"") -> WIECZOREK BAPTISTE | D7: =_xlfn.XLOOKUP(C7,Liste_Dossards!B:B,Liste_Dossards!C:C,"") -> LA TEAM COULEURS SAVOIE
A8: 7 | B8: 8 | C8: =_xlfn.XLOOKUP(B8,Liste_Dossards!A:A,Liste_Dossards!B:B,"") -> MUNSTERMAN NIELS | D8: =_xlfn.XLOOKUP(C8,Liste_Dossards!B:B,Liste_Dossards!C:C,"") -> UC PONTCHARRA
A9: 8 | B9: 12 | C9: =_xlfn.XLOOKUP(B9,Liste_Dossards!A:A,Liste_Dossards!B:B,"") -> CHAMBON | D9: =_xlfn.XLOOKUP(C9,Liste_Dossards!B:B,Liste_Dossards!C:C,"") -> LA TEAM COULEURS SAVOIE
A10: 9 | B10: 6 | C10: =_xlfn.XLOOKUP(B10,Liste_Dossards!A:A,Liste_Dossards!B:B,"") -> LAPIERRE NOE | D10: =_xlfn.XLOOKUP(C10,Liste_Dossards!B:B,Liste_Dossards!C:C,"") -> TEAM 3 MASSIFS
A11: 10 | B11: 5 | C11: =_xlfn.XLOOKUP(B11,Liste_Dossards!A:A,Liste_Dossards!B:B,"") -> LABORY JEREMY | D11: abd
A12: 11 | B12: 7 | C12: =_xlfn.XLOOKUP(B12,Liste_Dossards!A:A,Liste_Dossards!B:B,"") -> MAINGOT ALEXANDRE | D12: abd
A13: 12 | B13: 9 | C13: =_xlfn.XLOOKUP(B13,Liste_Dossards!A:A,Liste_Dossards!B:B,"") -> PERES PIERRE | D13: abd
A14: 13 | C14: =_xlfn.XLOOKUP(B14,Liste_Dossards!A:A,Liste_Dossards!B:B,"") -> 0 | D14: =_xlfn.XLOOKUP(C14,Liste_Dossards!B:B,Liste_Dossards!C:C,"")
A15: 14 | C15: =_xlfn.XLOOKUP(B15,Liste_Dossards!A:A,Liste_Dossards!B:B,"") -> 0 | D15: =_xlfn.XLOOKUP(C15,Liste_Dossards!B:B,Liste_Dossards!C:C,"")
A16: 15 | C16: =_xlfn.XLOOKUP(B16,Liste_Dossards!A:A,Liste_Dossards!B:B,"") -> 0 | D16: =_xlfn.XLOOKUP(C16,Liste_Dossards!B:B,Liste_Dossards!C:C,"")

Sheet Cat.2
A1: Classement Cat.2 | B1: N° de Dossard | C1: Nom Prénom | D1: Club
A2: 1 | B2: 19 | C2: =_xlfn.XLOOKUP(B2,Liste_Dossards!A:A,Liste_Dossards!B:B,"") -> COGNE SEBASTIEN | D2: =_xlfn.XLOOKUP(C2,Liste_Dossards!B:B,Liste_Dossards!C:C,"") -> 0
A3: 2 | B3: 34 | C3: =_xlfn.XLOOKUP(B3,Liste_Dossards!A:A,Liste_Dossards!B:B,"") -> SOURIMANT NICOLAS | D3: =_xlfn.XLOOKUP(C3,Liste_Dossards!B:B,Liste_Dossards!C:C,"") -> LE FONTANIL CYCLISME
A4: 3 | B4: 33 | C4: =_xlfn.XLOOKUP(B4,Liste_Dossards!A:A,Liste_Dossards!B:B,"") -> SANTALUCIA UGO | D4: =_xlfn.XLOOKUP(C4,Liste_Dossards!B:B,Liste_Dossards!C:C,"") -> TEAM 3 MASSIFS
A5: 4 | B5: 26 | C5: =_xlfn.XLOOKUP(B5,Liste_Dossards!A:A,Liste_Dossards!B:B,"") -> MAT CAMILLE | D5: =_xlfn.XLOOKUP(C5,Liste_Dossards!B:B,Liste_Dossards!C:C,"") -> TEAM JALLET AUTO
A6: 5 | B6: 15 | C6: =_xlfn.XLOOKUP(B6,Liste_Dossards!A:A,Liste_Dossards!B:B,"") -> BOISSY GUENAL | D6: =_xlfn.XLOOKUP(C6,Liste_Dossards!B:B,Liste_Dossards!C:C,"") -> UNION CYCLISTE VOIRONNAISE
A7: 6 | B7: 18 | C7: =_xlfn.XLOOKUP(B7,Liste_Dossards!A:A,Liste_Dossards!B:B,"") -> CLEMENT JUST | D7: =_xlfn.XLOOKUP(C7,Liste_Dossards!B:B,Liste_Dossards!C:C,"") -> TEAM 3 MASSIFS
A8: 7 | B8: 16 | C8: =_xlfn.XLOOKUP(B8,Liste_Dossards!A:A,Liste_Dossards!B:B,"") -> BOUVIER THOMAS | D8: =_xlfn.XLOOKUP(C8,Liste_Dossards!B:B,Liste_Dossards!C:C,"") -> UNION CYCLISTE DE PONTCHARRA GRESIVAUDAN
A9: 8 | B9: 23 | C9: =_xlfn.XLOOKUP(B9,Liste_Dossards!A:A,Liste_Dossards!B:B,"") -> JALLET WILLIAM | D9: =_xlfn.XLOOKUP(C9,Liste_Dossards!B:B,Liste_Dossards!C:C,"") -> TEAM JALLET AUTO
A10: 9 | B10: 17 | C10: =_xlfn.XLOOKUP(B10,Liste_Dossards!A:A,Liste_Dossards!B:B,"") -> CHERY Paul | D10: =_xlfn.XLOOKUP(C10,Liste_Dossards!B:B,Liste_Dossards!C:C,"") -> LE FONTANIL CYCLISME
A11: 10 | B11: 21 | C11: =_xlfn.XLOOKUP(B11,Liste_Dossards!A:A,Liste_Dossards!B:B,"") -> DELETROY AXEL | D11: =_xlfn.XLOOKUP(C11,Liste_Dossards!B:B,Liste_Dossards!C:C,"") -> LE FONTANIL CYCLISME
A12: 11 | B12: 20 | C12: =_xlfn.XLOOKUP(B12,Liste_Dossards!A:A,Liste_Dossards!B:B,"") -> COLLETTE MAXIME | D12: =_xlfn.XLOOKUP(C12,Liste_Dossards!B:B,Liste_Dossards!C:C,"") -> TEAM 3 MASSIFS
A13: 12 | B13: 27 | C13: =_xlfn.XLOOKUP(B13,Liste_Dossards!A:A,Liste_Dossards!B:B,"") -> MERLO RAPHAEL | D13: =_xlfn.XLOOKUP(C13,Liste_Dossards!B:B,Liste_Dossards!C:C,"") -> TEAM 3 MASSIFS
... A18: 17 | B18: 31 | C18: =_xlfn.XLOOKUP(B18,Liste_Dossards!A:A,Liste_Dossards!B:B,"") -> PINTUS EMMANUEL | D18: =_xlfn.XLOOKUP(C18,Liste_Dossards!B:B,Liste_Dossards!C:C,"") -> UNION CYCLISTE DE PONTCHARRA GRESIVAUDAN
A19: 18 | C19: =_xlfn.XLOOKUP(B19,Liste_Dossards!A:A,Liste_Dossards!B:B,"") -> 0 | D19: =_xlfn.XLOOKUP(C19,Liste_Dossards!B:B,Liste_Dossards!C:C,"")
A20: 19 | C20: =_xlfn.XLOOKUP(B20,Liste_Dossards!A:A,Liste_Dossards!B:B,"") -> 0 | D20: =_xlfn.XLOOKUP(C20,Liste_Dossards!B:B,Liste_Dossards!C:C,"")
A21: 20 | C21: =_xlfn.XLOOKUP(B21,Liste_Dossards!A:A,Liste_Dossards!B:B,"") -> 0 | D21: =_xlfn.XLOOKUP(C21,Liste_Dossards!B:B,Liste_Dossards!C:C,"")

Sheet Cat.3
A1: Classement Cat.3 | B1: N° de Dossard | C1: Nom Prénom | D1: Club
A2: 1 | B2: 63 | C2: =_xlfn.XLOOKUP(B2,Liste_Dossards!A:A,Liste_Dossards!B:B,"") -> PENEL STEPHANE | D2: =_xlfn.XLOOKUP(C2,Liste_Dossards!B:B,Liste_Dossards!C:C,"") -> VTT CHARTREUSE
A3: 2 | B3: 52 | C3: =_xlfn.XLOOKUP(B3,Liste_Dossards!A:A,Liste_Dossards!B:B,"") -> GATEAUX Damien | D3: =_xlfn.XLOOKUP(C3,Liste_Dossards!B:B,Liste_Dossards!C:C,"") -> JARRIE CHAMP SUR DRAC CYCLISME
A4: 3 | B4: 46 | C4: =_xlfn.XLOOKUP(B4,Liste_Dossards!A:A,Liste_Dossards!B:B,"") -> CARTIER STEPHANE | D4: =_xlfn.XLOOKUP(C4,Liste_Dossards!B:B,Liste_Dossards!C:C,"") -> JARRIE CHAMP SUR DRAC CYCLISME
A5: 4 | B5: 61 | C5: =_xlfn.XLOOKUP(B5,Liste_Dossards!A:A,Liste_Dossards!B:B,"") -> PARROT YVES | D5: =_xlfn.XLOOKUP(C5,Liste_Dossards!B:B,Liste_Dossards!C:C,"") -> UNION CYCLISTE VOIRONNAISE
A6: 5 | B6: 60 | C6: =_xlfn.XLOOKUP(B6,Liste_Dossards!A:A,Liste_Dossards!B:B,"") -> PAQUET DOMINIQUE | D6: =_xlfn.XLOOKUP(C6,Liste_Dossards!B:B,Liste_Dossards!C:C,"") -> RIVES UNION CYCLISTE
A7: 6 | B7: 56 | C7: =_xlfn.XLOOKUP(B7,Liste_Dossards!A:A,Liste_Dossards!B:B,"") -> LANDA MATTHIEU | D7: =_xlfn.XLOOKUP(C7,Liste_Dossards!B:B,Liste_Dossards!C:C,"") -> LA TEAM COULEURS SAVOIE
A8: 7 | B8: 53 | C8: =_xlfn.XLOOKUP(B8,Liste_Dossards!A:A,Liste_Dossards!B:B,"") -> GIANNONE JOSEPH | D8: =_xlfn.XLOOKUP(C8,Liste_Dossards!B:B,Liste_Dossards!C:C,"") -> UNION CYCLISTE VOIRONNAISE
A9: 8 | B9: 67 | C9: =_xlfn.XLOOKUP(B9,Liste_Dossards!A:A,Liste_Dossards!B:B,"") -> SEVOZ ARNAUD | D9: =_xlfn.XLOOKUP(C9,Liste_Dossards!B:B,Liste_Dossards!C:C,"") -> UNION CYCLISTE VOIRONNAISE
A10: 9 | B10: 51 | C10: =_xlfn.XLOOKUP(B10,Liste_Dossards!A:A,Liste_Dossards!B:B,"") -> DUCOL GILLES | D10: =_xlfn.XLOOKUP(C10,Liste_Dossards!B:B,Liste_Dossards!C:C,"") -> LA MOTTE SERVOLEX CYCLISME
A11: 10 | B11: 64 | C11: =_xlfn.XLOOKUP(B11,Liste_Dossards!A:A,Liste_Dossards!B:B,"") -> POMMIER NICOLAS | D11: =_xlfn.XLOOKUP(C11,Liste_Dossards!B:B,Liste_Dossards!C:C,"") -> LE FONTANIL CYCLISME
A12: 11 | B12: 47 | C12: =_xlfn.XLOOKUP(B12,Liste_Dossards!A:A,Liste_Dossards!B:B,"") -> CHAUMONT COLIN | D12: =_xlfn.XLOOKUP(C12,Liste_Dossards!B:B,Liste_Dossards!C:C,"") -> JARRIE CHAMP SUR DRAC CYCLISME
A13: 12 | B13: 43 | C13: =_xlfn.XLOOKUP(B13,Liste_Dossards!A:A,Liste_Dossards!B:B,"") -> BONNEFILLE ROMAIN | D13: =_xlfn.XLOOKUP(C13,Liste_Dossards!B:B,Liste_Dossards!C:C,"") -> TEAM 3 MASSIFS
... A28: 27 | B28: 45 | C28: =_xlfn.XLOOKUP(B28,Liste_Dossards!A:A,Liste_Dossards!B:B,"") -> BUISSON GREGORY | D28: =_xlfn.XLOOKUP(C28,Liste_Dossards!B:B,Liste_Dossards!C:C,"") -> UNION CYCLISTE DE PONTCHARRA GRESIVAUDAN
A29: 28 | C29: =_xlfn.XLOOKUP(B29,Liste_Dossards!A:A,Liste_Dossards!B:B,"") -> 0 | D29: =_xlfn.XLOOKUP(C29,Liste_Dossards!B:B,Liste_Dossards!C:C,"")
A30: 29 | C30: =_xlfn.XLOOKUP(B30,Liste_Dossards!A:A,Liste_Dossards!B:B,"") -> 0 | D30: =_xlfn.XLOOKUP(C30,Liste_Dossards!B:B,Liste_Dossards!C:C,"")
A31: 30 | C31: =_xlfn.XLOOKUP(B31,Liste_Dossards!A:A,Liste_Dossards!B:B,"") -> 0 | D31: =_xlfn.XLOOKUP(C31,Liste_Dossards!B:B,Liste_Dossards!C:C,"")
A32: 31 | C32: =_xlfn.XLOOKUP(B32,Liste_Dossards!A:A,Liste_Dossards!B:B,"") -> 0 | D32: =_xlfn.XLOOKUP(C32,Liste_Dossards!B:B,Liste_Dossards!C:C,"")
A33: 32 | C33: =_xlfn.XLOOKUP(B33,Liste_Dossards!A:A,Liste_Dossards!B:B,"") -> 0 | D33: =_xlfn.XLOOKUP(C33,Liste_Dossards!B:B,Liste_Dossards!C:C,"")

Sheet Cat.4
A1: Classement Cat.4 | B1: N° de Dossard | C1: Nom Prénom | D1: Club
A2: 1 | B2: 80 | C2: =_xlfn.XLOOKUP(B2,Liste_Dossards!A:A,Liste_Dossards!B:B,"") -> RAMBAUD JULIEN | D2: =_xlfn.XLOOKUP(C2,Liste_Dossards!B:B,Liste_Dossards!C:C,"") -> TEAM 3 MASSIFS
A3: 2 | B3: 75 | C3: =_xlfn.XLOOKUP(B3,Liste_Dossards!A:A,Liste_Dossards!B:B,"") -> BUSCAYLET PHILIPPE | D3: =_xlfn.XLOOKUP(C3,Liste_Dossards!B:B,Liste_Dossards!C:C,"") -> CYCLO CLUB DE GIERES
A4: 3 | B4: 85 | C4: =_xlfn.XLOOKUP(B4,Liste_Dossards!A:A,Liste_Dossards!B:B,"") -> GUILLERMIN ROLAND | D4: =_xlfn.XLOOKUP(C4,Liste_Dossards!B:B,Liste_Dossards!C:C,"") -> RIVES UNION CYCLISTE
A5: 4 | B5: 82 | C5: =_xlfn.XLOOKUP(B5,Liste_Dossards!A:A,Liste_Dossards!B:B,"") -> VALERO ANGELIQUE | D5: =_xlfn.XLOOKUP(C5,Liste_Dossards!B:B,Liste_Dossards!C:C,"") -> RIVES UNION CYCLISTE
A6: 5 | B6: 84 | C6: =_xlfn.XLOOKUP(B6,Liste_Dossards!A:A,Liste_Dossards!B:B,"") -> CHABOT GILLES | D6: =_xlfn.XLOOKUP(C6,Liste_Dossards!B:B,Liste_Dossards!C:C,"") -> Union cycliste du pays Gapencais
A7: 6 | B7: 76 | C7: =_xlfn.XLOOKUP(B7,Liste_Dossards!A:A,Liste_Dossards!B:B,"") -> HURSON NICOLAS | D7: =_xlfn.XLOOKUP(C7,Liste_Dossards!B:B,Liste_Dossards!C:C,"") -> TEAM 3 MASSIFS
A8: 7 | B8: 79 | C8: =_xlfn.XLOOKUP(B8,Liste_Dossards!A:A,Liste_Dossards!B:B,"") -> MOSCA PATRICK | D8: =_xlfn.XLOOKUP(C8,Liste_Dossards!B:B,Liste_Dossards!C:C,"") -> UNION CYCLISTE VOIRONNAISE
A9: 8 | B9: 78 | C9: =_xlfn.XLOOKUP(B9,Liste_Dossards!A:A,Liste_Dossards!B:B,"") -> MESSY PATRICK | D9: =_xlfn.XLOOKUP(C9,Liste_Dossards!B:B,Liste_Dossards!C:C,"") -> VELO CLUB DE PORC DE BOUC
A10: 9 | B10: 77 | C10: =_xlfn.XLOOKUP(B10,Liste_Dossards!A:A,Liste_Dossards!B:B,"") -> LOUPIEN VINCENT | D10: =_xlfn.XLOOKUP(C10,Liste_Dossards!B:B,Liste_Dossards!C:C,"") -> CYCLO CLUB DE GIERES
A11: 10 | B11: 81 | C11: =_xlfn.XLOOKUP(B11,Liste_Dossards!A:A,Liste_Dossards!B:B,"") -> SAUVAGE CYRIL | D11: =_xlfn.XLOOKUP(C11,Liste_Dossards!B:B,Liste_Dossards!C:C,"") -> UNION CYCLISTE DE PONTCHARRA GRESIVAUDAN
A12: 11 | B12: 83 | C12: =_xlfn.XLOOKUP(B12,Liste_Dossards!A:A,Liste_Dossards!B:B,"") -> CARTIER MILLION RAYMOND | D12: =_xlfn.XLOOKUP(C12,Liste_Dossards!B:B,Liste_Dossards!C:C,"") -> UNION CYCLISTE DE PONTCHARRA GRESIVAUDAN
A13: 12 | C13: =_xlfn.XLOOKUP(B13,Liste_Dossards!A:A,Liste_Dossards!B:B,"") -> 0 | D13: =_xlfn.XLOOKUP(C13,Liste_Dossards!B:B,Liste_Dossards!C:C,"")
A14: 13 | C14: =_xlfn.XLOOKUP(B14,Liste_Dossards!A:A,Liste_Dossards!B:B,"") -> 0 | D14: =_xlfn.XLOOKUP(C14,Liste_Dossards!B:B,Liste_Dossards!C:C,"")
A15: 14 | C15: =_xlfn.XLOOKUP(B15,Liste_Dossards!A:A,Liste_Dossards!B:B,"") -> 0 | D15: =_xlfn.XLOOKUP(C15,Liste_Dossards!B:B,Liste_Dossards!C:C,"")
A16: 15 | C16: =_xlfn.XLOOKUP(B16,Liste_Dossards!A:A,Liste_Dossards!B:B,"") -> 0 | D16: =_xlfn.XLOOKUP(C16,Liste_Dossards!B:B,Liste_Dossards!C:C,"")

Sheet Fem
A1: Classement Femmes | B1: N° de Dossard | C1: Nom Prénom | D1: Club
A2: 1 | B2: 89 | C2: =_xlfn.XLOOKUP(B2,Liste_Dossards!A:A,Liste_Dossards!B:B,"") -> SEVOZ LAVERDURE CELIA | D2: =_xlfn.XLOOKUP(C2,Liste_Dossards!B:B,Liste_Dossards!C:C,"") -> UNION CYCLISTE VOIRONNAISE
A3: 2 | B3: 86 | C3: =_xlfn.XLOOKUP(B3,Liste_Dossards!A:A,Liste_Dossards!B:B,"") -> COTE CHANTAL | D3: =_xlfn.XLOOKUP(C3,Liste_Dossards!B:B,Liste_Dossards!C:C,"") -> TEAM 3 MASSIFS
A4: 3 | B4: 87 | C4: =_xlfn.XLOOKUP(B4,Liste_Dossards!A:A,Liste_Dossards!B:B,"") -> ILNICKA OCEANE | D4: =_xlfn.XLOOKUP(C4,Liste_Dossards!B:B,Liste_Dossards!C:C,"") -> TEAM 3 MASSIFS
A5: 4 | B5: 88 | C5: =_xlfn.XLOOKUP(B5,Liste_Dossards!A:A,Liste_Dossards!B:B,"") -> SELIN KARINE | D5: =_xlfn.XLOOKUP(C5,Liste_Dossards!B:B,Liste_Dossards!C:C,"") -> UNION CYCLISTE VOIRONNAISE
A6: 5 | C6: =_xlfn.XLOOKUP(B6,Liste_Dossards!A:A,Liste_Dossards!B:B,"") -> 0 | D6: =_xlfn.XLOOKUP(C6,Liste_Dossards!B:B,Liste_Dossards!C:C,"")

Sheet U15_U16
A1: Classement U15/U16 | B1: N° de Dossard | C1: Nom Prénom | D1: Club
A2: 1 | B2: 93 | C2: =_xlfn.XLOOKUP(B2,Liste_Dossards!A:A,Liste_Dossards!B:B,"") -> HERNANDEZ RAFAEL | D2: =_xlfn.XLOOKUP(C2,Liste_Dossards!B:B,Liste_Dossards!C:C,"") -> UNION CYCLISTE VOIRONNAISE
A3: 2 | B3: 96 | C3: =_xlfn.XLOOKUP(B3,Liste_Dossards!A:A,Liste_Dossards!B:B,"") -> SELIN LOIC | D3: =_xlfn.XLOOKUP(C3,Liste_Dossards!B:B,Liste_Dossards!C:C,"") -> UNION CYCLISTE VOIRONNAISE
A4: 3 | B4: 94 | C4: =_xlfn.XLOOKUP(B4,Liste_Dossards!A:A,Liste_Dossards!B:B,"") -> LADURELLE CHARLES | D4: =_xlfn.XLOOKUP(C4,Liste_Dossards!B:B,Liste_Dossards!C:C,"") -> LMSC
A5: 4 | B5: 97 | C5: =_xlfn.XLOOKUP(B5,Liste_Dossards!A:A,Liste_Dossards!B:B,"") -> TANGUY MATHIS | D5: =_xlfn.XLOOKUP(C5,Liste_Dossards!B:B,Liste_Dossards!C:C,"") -> LA MOTTE SERVOLEX CYCLISME
A6: 5 | B6: 95 | C6: =_xlfn.XLOOKUP(B6,Liste_Dossards!A:A,Liste_Dossards!B:B,"") -> SAINTAIN-FANCHON RONAN | D6: =_xlfn.XLOOKUP(C6,Liste_Dossards!B:B,Liste_Dossards!C:C,"") -> UC VOIRONNAISE
A7: 6 | C7: =_xlfn.XLOOKUP(B7,Liste_Dossards!A:A,Liste_Dossards!B:B,"") -> 0 | D7: =_xlfn.XLOOKUP(C7,Liste_Dossards!B:B,Liste_Dossards!C:C,"")
A8: 7 | C8: =_xlfn.XLOOKUP(B8,Liste_Dossards!A:A,Liste_Dossards!B:B,"") -> 0 | D8: =_xlfn.XLOOKUP(C8,Liste_Dossards!B:B,Liste_Dossards!C:C,"")
A9: 8 | C9: =_xlfn.XLOOKUP(B9,Liste_Dossards!A:A,Liste_Dossards!B:B,"") -> 0 | D9: =_xlfn.XLOOKUP(C9,Liste_Dossards!B:B,Liste_Dossards!C:C,"")
A10: 9 | C10: =_xlfn.XLOOKUP(B10,Liste_Dossards!A:A,Liste_Dossards!B:B,"") -> 0 | D10: =_xlfn.XLOOKUP(C10,Liste_Dossards!B:B,Liste_Dossards!C:C,"")
A11: 10 | C11: =_xlfn.XLOOKUP(B11,Liste_Dossards!A:A,Liste_Dossards!B:B,"") -> 0 | D11: =_xlfn.XLOOKUP(C11,Liste_Dossards!B:B,Liste_Dossards!C:C,"")

Sheet Liste_Dossards
A1: Numéro de dossard | B1: Nom | C1: Club | D1: Licence | E1: Cat/val | F1: Affiliation | G1: Dossard récupéré | H1: Pièce d'identité
A2: 1 | B2: CONTI GUILLAUME | C2: TEAM JALLET AUTO | E2: 1re | F2: PASS
A3: 2 | B3: FRITSH NICOLAS | C3: UC VOIRONNAISE | E3: 1re | F3: PASS
A4: 3 | B4: GAUTHIER--PHILIPPE ERWIN | C4: LAC ALIANCE CYCLISTE | E4: 1re | F4: PASS
A5: 4 | B5: GIRAUD MATTHIEU | C5: UC RIVES | E5: 1re | F5: PASS
A6: 5 | B6: LABORY JEREMY | C6: LAC ALLIANCE CYCLISME | E6: 1re | F6: PASS
A7: 6 | B7: LAPIERRE NOE | C7: TEAM 3 MASSIFS | D7: 03893362655 | E7: 1re | F7: UFO
A8: 7 | B8: MAINGOT ALEXANDRE | C8: LAC ALLIANCE CYCLISME | E8: 1er | F8: PASS
A9: 8 | B9: MUNSTERMAN NIELS | C9: UC PONTCHARRA | E9: 1re | F9: PASS
A10: 9 | B10: PERES PIERRE | C10: LA TEAM COULEURS SAVOIE | E10: 1re | F10: PASS
A11: 10 | B11: VERNEY FREDERIC | C11: TEAM JALLET AUTO | E11: 1re | F11: PASS
A12: 11 | B12: WIECZOREK BAPTISTE | C12: LA TEAM COULEURS SAVOIE | E12: 1er | F12: PASS
A13: 12 | B13: CHAMBON | C13: LA TEAM COULEURS SAVOIE | E13: 1er | F13: UFO
A14: 13
A15: 14 | B15: BESCOND DIDIER | C15: JARRIE CHAMP SUR DRAC CYCLISME | D15: 03893317153 | E15: 2e | F15: UFO
A16: 15 | B16: BOISSY GUENAL | C16: UNION CYCLISTE VOIRONNAISE | E16: 2e | F16: PASS
A17: 16 | B17: BOUVIER THOMAS | C17: UNION CYCLISTE DE PONTCHARRA GRESIVAUDAN | E17: 2e | F17: UFO
A18: 17 | B18: CHERY Paul | C18: LE FONTANIL CYCLISME | D18: 03893357279 | E18: 2e | F18: UFO
A19: 18 | B19: CLEMENT JUST | C19: TEAM 3 MASSIFS | D19: 03893370646 | E19: 2e | F19: UFO
A20: 19 | B20: COGNE SEBASTIEN | E20: 2e | F20: PASS
A21: 20 | B21: COLLETTE MAXIME | C21: TEAM 3 MASSIFS | D21: 03893362713 | E21: 2e | F21: UFO
A22: 21 | B22: DELETROY AXEL | C22: LE FONTANIL CYCLISME | D22: 03893344230 | E22: 2e | F22: UFO
A23: 22 | B23: DOLLION MARGO | C23: TEAM ELLES | E23: 2e | F23: PASS
A24: 23 | B24: JALLET WILLIAM | C24: TEAM JALLET AUTO | E24: 2e | F24: PASS
A25: 24 | B25: LADURELLE BENOIT | C25: LMSC | E25: 2e | F25: PASS
A26: 25 | B26: LISI SAMUELE | C26: TEAM 3 MASSIFS | D26: 03893322279 | E26: 2e | F26: UFO
A27: 26 | B27: MAT CAMILLE | C27: TEAM JALLET AUTO | E27: 2e | F27: PASS
A28: 27 | B28: MERLO RAPHAEL | C28: TEAM 3 MASSIFS | D28: 03893361657 | E28: 2e | F28: UFO
A29: 28 | B29: MONGE NICOLAS | C29: LE FONTANIL CYCLISME | E29: 2e | F29: UFO
A30: 29 | B30: MORACCHIOLI THOMAS | C30: TEAM 3 MASSIFS | D30: 03893359805 | E30: 2e | F30: UFO
A31: 30 | B31: PUDELKO SEBASTIEN | C31: LA TRONCHE VELO SPORT | D31: 03893367145 | E31: 2e | F31: UFO
A32: 31 | B32: PINTUS EMMANUEL | C32: UNION CYCLISTE DE PONTCHARRA GRESIVAUDAN | E32: 2e | F32: UFO
A33: 32 | B33: RIPPERT VALENTIN | C33: UNION CYCLISTE DE PONTCHARRA GRESIVAUDAN | E33: 2e | F33: UFO
A34: 33 | B34: SANTALUCIA UGO | C34: TEAM 3 MASSIFS | D34: 03893368574 | E34: 2e | F34: UFO
A35: 34 | B35: SOURIMANT NICOLAS | C35: LE FONTANIL CYCLISME | E35: 2e | F35: UFO
A36: 35 | B36: TELLIER GUILLAUME | C36: UC RIVES | E36: 2e | F36: PASS
A37: 36 | B37: TRUC-VALLET THOMAS | C37: PAS DE CLUB | E37: 2e | F37: PASS
A38: 37 | B38: TRUPPA KEVIN | E38: 2e | F38: PASS
A39: 38 | B39: TROUPEL BENOIST | E39: 2e | F39: PASS
A40: 39 | B40: VILLAIN STEPHANE | E40: 2e | F40: PASS
...
